#VRML_SIM R2023b utf8

EXTERNPROTO "https://raw.githubusercontent.com/cyberbotics/webots/R2023b/projects/objects/backgrounds/protos/TexturedBackground.proto"
EXTERNPROTO "https://raw.githubusercontent.com/cyberbotics/webots/R2023b/projects/objects/backgrounds/protos/TexturedBackgroundLight.proto"
EXTERNPROTO "https://raw.githubusercontent.com/cyberbotics/webots/R2023b/projects/objects/floors/protos/RectangleArena.proto"

WorldInfo {
  basicTimeStep 1
  FPS 30
}
Viewpoint {
  orientation 0.1183934016556951 0.39370822268576555 -0.911579309678543 0.6372583169414135
  position -3.5498983695714923 2.69453899681175 1.4090116126913668
}
TexturedBackground {
}
TexturedBackgroundLight {
}
RectangleArena {
  floorSize 10 20
}
DEF A1 Robot {
  translation 0.01 3.64738e-08 0.27
  rotation 0 0 1 1.5708
  children [
    InertialUnit {
      name "IMU"
    }
    Accelerometer {
    }
    Gyro {
    }
    DEF trunk_visual CadShape {
      url [
        "../protos/meshes/trunk.dae"
      ]
    }
    Solid {
      children [
        Shape {
          appearance DEF red PBRAppearance {
            baseColor 0.5 0.5 0.5
            roughness 1
            metalness 0
          }
          geometry Box {
            size 0.001 0.001 0.001
          }
        }
      ]
      name "imu_link"
      physics Physics {
        density -1
        mass 0.001
        centerOfMass [
          0 0 0
        ]
        inertiaMatrix [
          0.0001 0.0001 0.0001
          0 0 0
        ]
      }
    }
    HingeJoint {
      jointParameters HingeJointParameters {
        anchor 0.183 -0.047 0
      }
      device [
        RotationalMotor {
          name "FR_hip_joint"
          maxVelocity 52.4
          minPosition -0.802851455917
          maxPosition 0.802851455917
          maxTorque 20
        }
        PositionSensor {
          name "FR_hip_joint_sensor"
        }
      ]
      endPoint Solid {
        translation 0.183 -0.047 0
        rotation 1 0 0 0
        children [
          Pose {
            rotation 1 0 0 3.141593
            children [
              DEF hip_visual CadShape {
                url [
                  "../protos/meshes/hip.dae"
                ]
              }
            ]
          }
          HingeJoint {
            jointParameters HingeJointParameters {
              position 0.78539816
              axis 0 1 0
              anchor 0 -0.08505 0
            }
            device [
              RotationalMotor {
                name "FR_thigh_joint"
                maxVelocity 28.6
                minPosition -1.0471975512
                maxPosition 4.18879020479
                maxTorque 55
              }
              PositionSensor {
                name "FR_thigh_joint_sensor"
              }
            ]
            endPoint Solid {
              translation 0 -0.08505 0
              rotation 0 0.9999999999999999 0 0.7853981599999997
              children [
                DEF thigh_mirror_visual CadShape {
                  url [
                    "../protos/meshes/thigh_mirror.dae"
                  ]
                }
                HingeJoint {
                  jointParameters HingeJointParameters {
                    position -1.806416
                    axis 0 1 0
                    anchor 0 0 -0.2
                  }
                  device [
                    RotationalMotor {
                      name "FR_calf_joint"
                      maxVelocity 28.6
                      minPosition -2.69653369433
                      maxPosition -0.916297857297
                      maxTorque 55
                    }
                    PositionSensor {
                      name "FR_calf_joint_sensor"
                    }
                  ]
                  endPoint Solid {
                    translation 0 0 -0.2
                    rotation 0 -1 0 1.806416
                    children [
                      DEF calf_visual CadShape {
                        url [
                          "../protos/meshes/calf.dae"
                        ]
                      }
                      Solid {
                        translation 0 0 -0.2
                        children [
                          Shape {
                            appearance DEF orange PBRAppearance {
                              baseColor 0.5 0.5 0.5
                              roughness 1
                              metalness 0
                            }
                            geometry Sphere {
                              radius 0.01
                            }
                          }
                        ]
                        name "FR_foot"
                        boundingObject Sphere {
                          radius 0.02
                        }
                        physics Physics {
                          density -1
                          mass 0.06
                          centerOfMass [
                            0 0 0
                          ]
                          inertiaMatrix [
                            9.6e-06 9.6e-06 9.6e-06
                            0 0 0
                          ]
                        }
                      }
                    ]
                    name "FR_calf"
                    boundingObject Pose {
                      translation 0 0 -0.1
                      rotation 0 1 0 1.570796
                      children [
                        Box {
                          size 0.2 0.016 0.016
                        }
                      ]
                    }
                    physics Physics {
                      density -1
                      mass 0.166
                      centerOfMass [
                        0.006435 0 -0.107388
                      ]
                      inertiaMatrix [
                        0.002997972 0.003014022 3.2426e-05
                        0 -0.000141163 0
                      ]
                    }
                  }
                }
              ]
              name "FR_thigh"
              boundingObject Pose {
                translation 0 0 -0.1
                rotation 0 1 0 1.570796
                children [
                  Box {
                    size 0.2 0.0245 0.034
                  }
                ]
              }
              physics Physics {
                density -1
                mass 1.013
                centerOfMass [
                  -0.003237 0.022327 -0.027326
                ]
                inertiaMatrix [
                  0.005529065 0.005139339 0.001367788
                  -4.825e-06 0.000343869 -2.2448e-05
                ]
              }
            }
          }
        ]
        name "FR_hip"
        physics Physics {
          density -1
          mass 0.696
          centerOfMass [
            -0.003311 -0.000635 3.1e-05
          ]
          inertiaMatrix [
            0.000469246 0.00080749 0.000552929
            9.409e-06 -3.42e-07 4.66e-07
          ]
        }
      }
    }
    HingeJoint {
      jointParameters HingeJointParameters {
        anchor 0.183 0.047 0
      }
      device [
        RotationalMotor {
          name "FL_hip_joint"
          maxVelocity 52.4
          minPosition -0.802851455917
          maxPosition 0.802851455917
          maxTorque 20
        }
        PositionSensor {
          name "FL_hip_joint_sensor"
        }
      ]
      endPoint Solid {
        translation 0.183 0.047 0
        rotation 1 0 0 0
        children [
          USE hip_visual
          HingeJoint {
            jointParameters HingeJointParameters {
              position 0.78539816
              axis 0 1 0
              anchor 0 0.08505 0
            }
            device [
              RotationalMotor {
                name "FL_thigh_joint"
                maxVelocity 28.6
                minPosition -1.0471975512
                maxPosition 4.18879020479
                maxTorque 55
              }
              PositionSensor {
                name "FL_thigh_joint_sensor"
              }
            ]
            endPoint Solid {
              translation 0 0.08505 0
              rotation 0 0.9999999999999999 0 0.7853981599999997
              children [
                DEF thigh_visual CadShape {
                  url [
                    "../protos/meshes/thigh.dae"
                  ]
                }
                HingeJoint {
                  jointParameters HingeJointParameters {
                    position -1.806416
                    axis 0 1 0
                    anchor 0 0 -0.2
                  }
                  device [
                    RotationalMotor {
                      name "FL_calf_joint"
                      maxVelocity 28.6
                      minPosition -2.69653369433
                      maxPosition -0.916297857297
                      maxTorque 55
                    }
                    PositionSensor {
                      name "FL_calf_joint_sensor"
                    }
                  ]
                  endPoint Solid {
                    translation 0 0 -0.2
                    rotation 0 -1 0 1.806416
                    children [
                      USE calf_visual
                      Solid {
                        translation 0 0 -0.2
                        children [
                          Shape {
                            appearance USE orange
                            geometry Sphere {
                              radius 0.01
                            }
                          }
                        ]
                        name "FL_foot"
                        boundingObject Sphere {
                          radius 0.02
                        }
                        physics Physics {
                          density -1
                          mass 0.06
                          centerOfMass [
                            0 0 0
                          ]
                          inertiaMatrix [
                            9.6e-06 9.6e-06 9.6e-06
                            0 0 0
                          ]
                        }
                      }
                    ]
                    name "FL_calf"
                    boundingObject Pose {
                      translation 0 0 -0.1
                      rotation 0 1 0 1.570796
                      children [
                        Box {
                          size 0.2 0.016 0.016
                        }
                      ]
                    }
                    physics Physics {
                      density -1
                      mass 0.166
                      centerOfMass [
                        0.006435 0 -0.107388
                      ]
                      inertiaMatrix [
                        0.002997972 0.003014022 3.2426e-05
                        0 -0.000141163 0
                      ]
                    }
                  }
                }
              ]
              name "FL_thigh"
              boundingObject Pose {
                translation 0 0 -0.1
                rotation 0 1 0 1.570796
                children [
                  Box {
                    size 0.2 0.0245 0.034
                  }
                ]
              }
              physics Physics {
                density -1
                mass 1.013
                centerOfMass [
                  -0.003237 -0.022327 -0.027326
                ]
                inertiaMatrix [
                  0.005529065 0.005139339 0.001367788
                  4.825e-06 0.000343869 2.2448e-05
                ]
              }
            }
          }
        ]
        name "FL_hip"
        physics Physics {
          density -1
          mass 0.696
          centerOfMass [
            -0.003311 0.000635 3.1e-05
          ]
          inertiaMatrix [
            0.000469246 0.00080749 0.000552929
            -9.409e-06 -3.42e-07 -4.66e-07
          ]
        }
      }
    }
    HingeJoint {
      jointParameters HingeJointParameters {
        anchor -0.183 -0.047 0
      }
      device [
        RotationalMotor {
          name "RR_hip_joint"
          maxVelocity 52.4
          minPosition -0.802851455917
          maxPosition 0.802851455917
          maxTorque 20
        }
        PositionSensor {
          name "RR_hip_joint_sensor"
        }
      ]
      endPoint Solid {
        translation -0.183 -0.047 0
        rotation 1 0 0 0
        children [
          Pose {
            rotation 0 0 -1 3.141593
            children [
              USE hip_visual
            ]
          }
          HingeJoint {
            jointParameters HingeJointParameters {
              position 0.78539816
              axis 0 1 0
              anchor 0 -0.08505 0
            }
            device [
              RotationalMotor {
                name "RR_thigh_joint"
                maxVelocity 28.6
                minPosition -1.0471975512
                maxPosition 4.18879020479
                maxTorque 55
              }
              PositionSensor {
                name "RR_thigh_joint_sensor"
              }
            ]
            endPoint Solid {
              translation 0 -0.08505 0
              rotation 0 0.9999999999999999 0 0.7853981599999997
              children [
                USE thigh_mirror_visual
                HingeJoint {
                  jointParameters HingeJointParameters {
                    position -1.806416
                    axis 0 1 0
                    anchor 0 0 -0.2
                  }
                  device [
                    RotationalMotor {
                      name "RR_calf_joint"
                      maxVelocity 28.6
                      minPosition -2.69653369433
                      maxPosition -0.916297857297
                      maxTorque 55
                    }
                    PositionSensor {
                      name "RR_calf_joint_sensor"
                    }
                  ]
                  endPoint Solid {
                    translation 0 0 -0.2
                    rotation 0 -1 0 1.806416
                    children [
                      USE calf_visual
                      Solid {
                        translation 0 0 -0.2
                        children [
                          Shape {
                            appearance USE orange
                            geometry Sphere {
                              radius 0.01
                            }
                          }
                        ]
                        name "RR_foot"
                        boundingObject Sphere {
                          radius 0.02
                        }
                        physics Physics {
                          density -1
                          mass 0.06
                          centerOfMass [
                            0 0 0
                          ]
                          inertiaMatrix [
                            9.6e-06 9.6e-06 9.6e-06
                            0 0 0
                          ]
                        }
                      }
                    ]
                    name "RR_calf"
                    boundingObject Pose {
                      translation 0 0 -0.1
                      rotation 0 1 0 1.570796
                      children [
                        Box {
                          size 0.2 0.016 0.016
                        }
                      ]
                    }
                    physics Physics {
                      density -1
                      mass 0.166
                      centerOfMass [
                        0.006435 0 -0.107388
                      ]
                      inertiaMatrix [
                        0.002997972 0.003014022 3.2426e-05
                        0 -0.000141163 0
                      ]
                    }
                  }
                }
              ]
              name "RR_thigh"
              boundingObject Pose {
                translation 0 0 -0.1
                rotation 0 1 0 1.570796
                children [
                  Box {
                    size 0.2 0.0245 0.034
                  }
                ]
              }
              physics Physics {
                density -1
                mass 1.013
                centerOfMass [
                  -0.003237 0.022327 -0.027326
                ]
                inertiaMatrix [
                  0.005529065 0.005139339 0.001367788
                  -4.825e-06 0.000343869 -2.2448e-05
                ]
              }
            }
          }
        ]
        name "RR_hip"
        physics Physics {
          density -1
          mass 0.696
          centerOfMass [
            0.003311 -0.000635 3.1e-05
          ]
          inertiaMatrix [
            0.000469246 0.00080749 0.000552929
            -9.409e-06 3.42e-07 4.66e-07
          ]
        }
      }
    }
    HingeJoint {
      jointParameters HingeJointParameters {
        anchor -0.183 0.047 0
      }
      device [
        RotationalMotor {
          name "RL_hip_joint"
          maxVelocity 52.4
          minPosition -0.802851455917
          maxPosition 0.802851455917
          maxTorque 20
        }
        PositionSensor {
          name "RL_hip_joint_sensor"
        }
      ]
      endPoint Solid {
        translation -0.183 0.047 0
        rotation 1 0 0 0
        children [
          Pose {
            rotation 0 1 0 3.141593
            children [
              USE hip_visual
            ]
          }
          HingeJoint {
            jointParameters HingeJointParameters {
              position 0.78539816
              axis 0 1 0
              anchor 0 0.08505 0
            }
            device [
              RotationalMotor {
                name "RL_thigh_joint"
                maxVelocity 28.6
                minPosition -1.0471975512
                maxPosition 4.18879020479
                maxTorque 55
              }
              PositionSensor {
                name "RL_thigh_joint_sensor"
              }
            ]
            endPoint Solid {
              translation 0 0.08505 0
              rotation 0 0.9999999999999999 0 0.7853981599999997
              children [
                USE thigh_visual
                HingeJoint {
                  jointParameters HingeJointParameters {
                    position -1.806416
                    axis 0 1 0
                    anchor 0 0 -0.2
                  }
                  device [
                    RotationalMotor {
                      name "RL_calf_joint"
                      maxVelocity 28.6
                      minPosition -2.69653369433
                      maxPosition -0.916297857297
                      maxTorque 55
                    }
                    PositionSensor {
                      name "RL_calf_joint_sensor"
                    }
                  ]
                  endPoint Solid {
                    translation 0 0 -0.2
                    rotation 0 -1 0 1.806416
                    children [
                      USE calf_visual
                      Solid {
                        translation 0 0 -0.2
                        children [
                          Shape {
                            appearance USE orange
                            geometry Sphere {
                              radius 0.01
                            }
                          }
                        ]
                        name "RL_foot"
                        boundingObject Sphere {
                          radius 0.02
                        }
                        physics Physics {
                          density -1
                          mass 0.06
                          centerOfMass [
                            0 0 0
                          ]
                          inertiaMatrix [
                            9.6e-06 9.6e-06 9.6e-06
                            0 0 0
                          ]
                        }
                      }
                    ]
                    name "RL_calf"
                    boundingObject Pose {
                      translation 0 0 -0.1
                      rotation 0 1 0 1.570796
                      children [
                        Box {
                          size 0.2 0.016 0.016
                        }
                      ]
                    }
                    physics Physics {
                      density -1
                      mass 0.166
                      centerOfMass [
                        0.006435 0 -0.107388
                      ]
                      inertiaMatrix [
                        0.002997972 0.003014022 3.2426e-05
                        0 -0.000141163 0
                      ]
                    }
                  }
                }
              ]
              name "RL_thigh"
              boundingObject Pose {
                translation 0 0 -0.1
                rotation 0 1 0 1.570796
                children [
                  Box {
                    size 0.2 0.0245 0.034
                  }
                ]
              }
              physics Physics {
                density -1
                mass 1.013
                centerOfMass [
                  -0.003237 -0.022327 -0.027326
                ]
                inertiaMatrix [
                  0.005529065 0.005139339 0.001367788
                  4.825e-06 0.000343869 2.2448e-05
                ]
              }
            }
          }
        ]
        name "RL_hip"
        physics Physics {
          density -1
          mass 0.696
          centerOfMass [
            0.003311 0.000635 3.1e-05
          ]
          inertiaMatrix [
            0.000469246 0.00080749 0.000552929
            9.409e-06 3.42e-07 -4.66e-07
          ]
        }
      }
    }
  ]
  name "A1"
  boundingObject Box {
    size 0.267 0.194 0.114
  }
  physics Physics {
    density -1
    mass 4.713
    centerOfMass [
      0.012731 0.002186 0.000515
    ]
    inertiaMatrix [
      0.01683993 0.05657903 0.0647136
      8.3902e-05 0.000597679 2.5134e-05
    ]
  }
  controller "<extern>"
  supervisor TRUE
}
